Workbook

Sheet Informações Editora Globo e SGR
A1: EMPRESA | B1: MAT | C1: NOME | D1: CARGO (SEM SENIORIDADE) | E1: LOCALIZAÇÃO | F1: CCUSTO | G1: DIRETORIA | H1: ÁREA | I1: MAT GESTOR | J1: GESTOR | K1: CCUSTO SAP
A2: 10 | B2: 110015 | C2: ANDRE FELIPE MARSON DE ANDRADE | D2: ADMINISTRADOR BANCO DE DADOS | E2: São Paulo | F2: 1142080000 | G2: TECNOLOGIA | H2: INFRAESTRUTURA TI | I2: 284913 | J2: DOUGLAS PEREIRA DA SILVA | K2: =VLOOKUP(A2,Empresas!C:E,3,0)&F2 -> 1142080000
A3: 10 | B3: 109823 | C3: RODRIGO DONIZETE PALOMBO CABRERA | D3: ADMINISTRADOR REDES | E3: São Paulo | F3: 1142080000 | G3: TECNOLOGIA | H3: INFRAESTRUTURA TI | I3: 284913 | J3: DOUGLAS PEREIRA DA SILVA | K3: =VLOOKUP(A3,Empresas!C:E,3,0)&F3 -> 1142080000
A4: 10 | B4: 284943 | C4: ANA BEATRIZ VIEIRA PODESTA | D4: ADVOGADO | E4: Rio de Janeiro | F4: 1121400000 | G4: JURÍDICO | H4: TRABALHISTA E PREVIDENCIÁRIO | I4: 108394 | J4: PRISCILA CAMPOS DE ALMEIDA FELIX | K4: =VLOOKUP(A4,Empresas!C:E,3,0)&F4 -> 1121400000
A5: 10 | B5: 283767 | C5: KAROLINE MENDONCA DE OLIVEIRA | D5: ADVOGADO | E5: Rio de Janeiro | F5: 1121400000 | G5: JURÍDICO | H5: CIVEL E CONSUMIDOR | I5: 108394 | J5: PRISCILA CAMPOS DE ALMEIDA FELIX | K5: =VLOOKUP(A5,Empresas!C:E,3,0)&F5 -> 1121400000
A6: 10 | B6: 284541 | C6: ALEANDRA RIBEIRO NASCIMENTO | D6: ADVOGADO | E6: Rio de Janeiro | F6: 1121400000 | G6: JURÍDICO | H6: CIVEL E CONSUMIDOR | I6: 108394 | J6: PRISCILA CAMPOS DE ALMEIDA FELIX | K6: =VLOOKUP(A6,Empresas!C:E,3,0)&F6 -> 1121400000
A7: 10 | B7: 285104 | C7: JULYANA MADEIRA CORREA | D7: ADVOGADO | E7: Rio de Janeiro | F7: 1121400000 | G7: JURÍDICO | H7: TRIBUTARIO, SOCIETARIO E REGULATORIO | I7: 108394 | J7: PRISCILA CAMPOS DE ALMEIDA FELIX | K7: =VLOOKUP(A7,Empresas!C:E,3,0)&F7 -> 1121400000
A8: 10 | B8: 284829 | C8: FERNANDA NEVES DE FARIAS | D8: ADVOGADO | E8: Rio de Janeiro | F8: 1121400000 | G8: JURÍDICO | H8: CIVEL E CONSUMIDOR | I8: 108394 | J8: PRISCILA CAMPOS DE ALMEIDA FELIX | K8: =VLOOKUP(A8,Empresas!C:E,3,0)&F8 -> 1121400000
A9: 10 | B9: 284022 | C9: GABRIEL FREGNI ALFIERI | D9: ADVOGADO | E9: São Paulo | F9: 1121400000 | G9: JURÍDICO | H9: TRABALHISTA E PREVIDENCIÁRIO | I9: 284949 | J9: SAMARA PESSANHA VINHOSA | K9: =VLOOKUP(A9,Empresas!C:E,3,0)&F9 -> 1121400000
A10: 10 | B10: 108908 | C10: MARY ANNE MOURA | D10: ADVOGADO | E10: Rio de Janeiro | F10: 1121400000 | G10: JURÍDICO | H10: CIVEL E CONSUMIDOR | I10: 108394 | J10: PRISCILA CAMPOS DE ALMEIDA FELIX | K10: =VLOOKUP(A10,Empresas!C:E,3,0)&F10 -> 1121400000
A11: 10 | B11: 108096 | C11: CARLOS ALBERTO BATISTA | D11: ALMOXARIFE | E11: Parque Gráfico | F11: 1141210000 | G11: SERVIÇOS IMPRESSOS | H11: LOGISTICA OPERACIONAL | I11: 108140 | J11: JOSE RICARDO DE LUCENA | K11: =VLOOKUP(A11,Empresas!C:E,3,0)&F11 -> 1141210000
A12: 10 | B12: 108408 | C12: EDSON GRIPE | D12: ALMOXARIFE | E12: Parque Gráfico | F12: 1141210000 | G12: SERVIÇOS IMPRESSOS | H12: LOGISTICA OPERACIONAL | I12: 108140 | J12: JOSE RICARDO DE LUCENA | K12: =VLOOKUP(A12,Empresas!C:E,3,0)&F12 -> 1141210000
A13: 10 | B13: 281957 | C13: EMANUEL DE LIMA FERNANDES | D13: ALMOXARIFE | E13: Parque Gráfico | F13: 1141210000 | G13: SERVIÇOS IMPRESSOS | H13: LOGISTICA OPERACIONAL | I13: 108140 | J13: JOSE RICARDO DE LUCENA | K13: =VLOOKUP(A13,Empresas!C:E,3,0)&F13 -> 1141210000
... A15: 10 | B15: 281961 | C15: WILLIAM PEREIRA DA SILVA JUNIOR | D15: ALMOXARIFE | E15: Parque Gráfico | F15: 1141210000 | G15: SERVIÇOS IMPRESSOS | H15: LOGISTICA OPERACIONAL | I15: 108140 | J15: JOSE RICARDO DE LUCENA | K15: =VLOOKUP(A15,Empresas!C:E,3,0)&F15 -> 1141210000
A16: 10 | B16: 100735 | C16: HELIO JOSE DA SILVA | D16: ANALISTA | E16: São Paulo | F16: 1122360000 | G16: LICENCIADOS BENEFICIOS | H16: LICENCIADOS BENEFICIOS | I16: - | J16: SEM GESTOR | K16: =VLOOKUP(A16,Empresas!C:E,3,0)&F16 -> 1122360000
A17: 10 | B17: 107488 | C17: PEDRO OLIVEIRA DA SILVA | D17: ANALISTA | E17: São Paulo | F17: 1431351400 | G17: AUDIÊNCIA | H17: VENDAS INDIRETAS | I17: 109048 | J17: MARIO JORGE DA SILVA PERRUT | K17: =VLOOKUP(A17,Empresas!C:E,3,0)&F17 -> 1431351400
A18: 10 | B18: 284476 | C18: KALINE DA SILVA LIMA | D18: ANALISTA | E18: Rio de Janeiro | F18: 1121110000 | G18: FINANÇAS | H18: OPERACOES FINANCEIRAS | I18: 108047 | J18: ANDREA DE ALMEIDA AMAT | K18: =VLOOKUP(A18,Empresas!C:E,3,0)&F18 -> 1121110000
A19: 10 | B19: 108861 | C19: ELLEN CRYS DE MENESES | D19: ANALISTA | E19: Rio de Janeiro | F19: 1121300000 | G19: INFRAESTRUTURA | H19: GESTÃO | I19: 108346 | J19: MAURICIO CESAR MORAES SILVA | K19: =VLOOKUP(A19,Empresas!C:E,3,0)&F19 -> 1121300000
A20: 10 | B20: 284711 | C20: JORGE LIBERATO SILVA DE JESUS | D20: ANALISTA | E20: Rio de Janeiro | F20: 1121400000 | G20: JURÍDICO | H20: ADMINISTRATIVO | I20: 108394 | J20: PRISCILA CAMPOS DE ALMEIDA FELIX | K20: =VLOOKUP(A20,Empresas!C:E,3,0)&F20 -> 1121400000
A21: 10 | B21: 283208 | C21: TEREZA CRISTINA DE CARVALHO ABDALA | D21: ANALISTA | E21: Rio de Janeiro | F21: 1121720000 | G21: FINANÇAS | H21: PLANEJAMENTO TRIBUTÁRIO | I21: 284394 | J21: MARIA DO CARMO MADUREIRA RUA | K21: =VLOOKUP(A21,Empresas!C:E,3,0)&F21 -> 1121720000
A22: 10 | B22: 107852 | C22: CESAR MEDEIROS FALCAO | D22: ANALISTA | E22: Rio de Janeiro | F22: 1122360000 | G22: LICENCIADOS BENEFICIOS | H22: LICENCIADOS BENEFICIOS | I22: - | J22: SEM GESTOR | K22: =VLOOKUP(A22,Empresas!C:E,3,0)&F22 -> 1122360000
A23: 10 | B23: 283452 | C23: LUANA DE AGUIAR GONCALVES | D23: ANALISTA | E23: Rio de Janeiro | F23: 1131361000 | G23: AUDIÊNCIA | H23: PLANEJAMENTO COMERCIAL | I23: 108708 | J23: ISIS LEMOS DE OLIVEIRA | K23: =VLOOKUP(A23,Empresas!C:E,3,0)&F23 -> 1131361000
A24: 10 | B24: 283684 | C24: DAYARA LIMA PEREIRA DE SOUZA | D24: ANALISTA | E24: Parque Gráfico | F24: 1141140000 | G24: SERVIÇOS IMPRESSOS | H24: INFRAESTRUTURA PG | I24: 108136 | J24: GEORGE FERNANDES PIMENTEL | K24: =VLOOKUP(A24,Empresas!C:E,3,0)&F24 -> 1141140000
A25: 10 | B25: 284273 | C25: SAMARA DOS SANTOS BATISTA | D25: ANALISTA | E25: Parque Gráfico | F25: 1141140000 | G25: SERVIÇOS IMPRESSOS | H25: INFRAESTRUTURA PG | I25: 108136 | J25: GEORGE FERNANDES PIMENTEL | K25: =VLOOKUP(A25,Empresas!C:E,3,0)&F25 -> 1141140000
A26: 10 | B26: 284742 | C26: FELIPE BERNARDO DA ROCHA | D26: ANALISTA | E26: Parque Gráfico | F26: 1143331107 | G26: SERVIÇOS IMPRESSOS | H26: ENTREGA DOMICILIAR | I26: 108148 | J26: ADRIANA PAULINO DA SILVA | K26: =VLOOKUP(A26,Empresas!C:E,3,0)&F26 -> 1143331107
A27: 10 | B27: 283824 | C27: ABNER LUCAS DOS SANTOS TEIXEIRA | D27: ANALISTA | E27: Rio de Janeiro | F27: 1121090000 | G27: FINANÇAS | H27: FLUXO DE CAIXA E COMISSÃO | I27: 281969 | J27: BRUNO LEONARDO COSTA SEQUEIRA | K27: =VLOOKUP(A27,Empresas!C:E,3,0)&F27 -> 1121090000
A28: 10 | B28: 284201 | C28: BARBARA DE SANTANA PINTO MOREIRA | D28: ANALISTA | E28: Rio de Janeiro | F28: 1152405000 | G28: DESENVOLVIMENTO COMERCIAL | H28: DIGITAL | I28: 108424 | J28: LEANDRO QUEIROZ FIGUEIRA | K28: =VLOOKUP(A28,Empresas!C:E,3,0)&F28 -> 1152405000
A29: 10 | B29: 284766 | C29: CLARA LIZZE PEREIRA DA SILVA | D29: ANALISTA | E29: Rio de Janeiro | F29: 1152405000 | G29: DESENVOLVIMENTO COMERCIAL | H29: DIGITAL | I29: 283248 | J29: ISADORA ANCORA DA LUZ DAMASCENO | K29: =VLOOKUP(A29,Empresas!C:E,3,0)&F29 -> 1152405000
A30: 10 | B30: 283167 | C30: THAYSA LEITE DA SILVA | D30: ANALISTA | E30: Rio de Janeiro | F30: 1152405000 | G30: DESENVOLVIMENTO COMERCIAL | H30: DIGITAL | I30: 109106 | J30: RAFAEL DE SA CENDON | K30: =VLOOKUP(A30,Empresas!C:E,3,0)&F30 -> 1152405000
A31: 10 | B31: 284667 | C31: MARIA CLARA HOMAISSI DA SILVA | D31: ANALISTA | E31: Rio de Janeiro | F31: 1152703000 | G31: DESENVOLVIMENTO COMERCIAL | H31: EVENTO | I31: 282119 | J31: CARLA DE SIMONE FERREIRA MONTENEGRO | K31: =VLOOKUP(A31,Empresas!C:E,3,0)&F31 -> 1152703000
A32: 10 | B32: 283874 | C32: BRUNA TEIXEIRA VELOSO DA FONSECA | D32: ANALISTA | E32: Rio de Janeiro | F32: 1153223000 | G32: DESENVOLVIMENTO COMERCIAL | H32: MKT PUBLICITÁRIO | I32: 108868 | J32: RAPHAEL DE BARROS RASMUSEN AMAYA | K32: =VLOOKUP(A32,Empresas!C:E,3,0)&F32 -> 1153223000
A33: 10 | B33: 285117 | C33: JULIA GRACIOLI CORREA DE SA | D33: ANALISTA | E33: Rio de Janeiro | F33: 1153223000 | G33: DESENVOLVIMENTO COMERCIAL | H33: MKT PUBLICITÁRIO | I33: 108868 | J33: RAPHAEL DE BARROS RASMUSEN AMAYA | K33: =VLOOKUP(A33,Empresas!C:E,3,0)&F33 -> 1153223000
A34: 10 | B34: 284573 | C34: BIANCA SABIONI BOECHAT ZWIRMAN | D34: ANALISTA | E34: Rio de Janeiro | F34: 1153223000 | G34: DESENVOLVIMENTO COMERCIAL | H34: MKT PUBLICITÁRIO | I34: 108868 | J34: RAPHAEL DE BARROS RASMUSEN AMAYA | K34: =VLOOKUP(A34,Empresas!C:E,3,0)&F34 -> 1153223000
... A150: 10 | B150: 108443 | C150: CATERINE JUNKO OKUMURA | D150: ANALISTA SAP ABAP | E150: Rio de Janeiro | F150: 1142600000 | G150: TECNOLOGIA | H150: SISTEMAS CORPORATIVOS | I150: 100571 | J150: RITA DE CASSIA MUTARELLI | K150: =VLOOKUP(A150,Empresas!C:E,3,0)&F150 -> 1142600000
A151: 10 | B151: 100810 | C151: MARTA NOVATO DE CARVALHO | D151: ANALISTA SERVICOS CLIENTE | E151: São Paulo | F151: 1122360000 | G151: LICENCIADOS BENEFICIOS | H151: LICENCIADOS BENEFICIOS | I151: - | J151: SEM GESTOR | K151: =VLOOKUP(A151,Empresas!C:E,3,0)&F151 -> 1122360000
A152: 10 | B152: 109791 | C152: ADENIR BARBOSA DE SOUZA | D152: ANALISTA TESTES | E152: São Paulo | F152: 1142034500 | G152: SISTEMA PRO | H152: DESENVOLVIMENTO DIGITAL - SISTEMA PRO | I152: 109677 | J152: DIOGO GUZELIAN BENTO | K152: =VLOOKUP(A152,Empresas!C:E,3,0)&F152 -> 1142034500
A153: 10 | B153: 109742 | C153: CARINA PIVA RIBEIRO | D153: ANALISTA TESTES | E153: São Paulo | F153: 1142034500 | G153: SISTEMA PRO | H153: DESENVOLVIMENTO DIGITAL - SISTEMA PRO | I153: 109677 | J153: DIOGO GUZELIAN BENTO | K153: =VLOOKUP(A153,Empresas!C:E,3,0)&F153 -> 1142034500
A154: 10 | B154: 109712 | C154: KLEBER TAKAHASHI DA SILVA | D154: ANALISTA TESTES | E154: São Paulo | F154: 1142034500 | G154: SISTEMA PRO | H154: DESENVOLVIMENTO DIGITAL - SISTEMA PRO | I154: 109677 | J154: DIOGO GUZELIAN BENTO | K154: =VLOOKUP(A154,Empresas!C:E,3,0)&F154 -> 1142034500
A155: 10 | B155: 282768 | C155: JAQUES GUIMARAES DE FREITAS | D155: ANALISTA TESTES | E155: São Paulo | F155: 1142034500 | G155: SISTEMA PRO | H155: DESENVOLVIMENTO DIGITAL - SISTEMA PRO | I155: 109677 | J155: DIOGO GUZELIAN BENTO | K155: =VLOOKUP(A155,Empresas!C:E,3,0)&F155 -> 1142034500
A156: 10 | B156: 282659 | C156: KARINA CRISTINA DA SILVA | D156: ANALISTA TESTES | E156: São Paulo | F156: 1142034500 | G156: SISTEMA PRO | H156: DESENVOLVIMENTO DIGITAL - SISTEMA PRO | I156: 109677 | J156: DIOGO GUZELIAN BENTO | K156: =VLOOKUP(A156,Empresas!C:E,3,0)&F156 -> 1142034500
...

Sheet Empresas
B2: EMPRESA | C2: CÓDIGO | D2: NOME | E2: LETRA
B3: SGR | C3: 571 | D3: RÁDIO GLOBO | E3: G
B4: SGR | C4: 572 | D4: BH | E4: H
B5: SGR | C5: 573 | D5: CAETÉ | E5: T
B6: SGR | C6: 574 | D6: EXCELSIOR | E6: X
B7: SGR | C7: 575 | D7: ELDORADO | E7: E
B8: EG | C8: 10 | D8: EDITORA GLOBO
